[2023-04-15 06:12:30,716] {taskinstance.py:877} INFO - Dependencies all met for <TaskInstance: spotify_final_dag.create_table 2023-04-15T01:00:00+00:00 [queued]>
[2023-04-15 06:12:31,289] {taskinstance.py:877} INFO - Dependencies all met for <TaskInstance: spotify_final_dag.create_table 2023-04-15T01:00:00+00:00 [queued]>
[2023-04-15 06:12:31,328] {taskinstance.py:1068} INFO - 
--------------------------------------------------------------------------------
[2023-04-15 06:12:31,339] {taskinstance.py:1069} INFO - Starting attempt 1 of 2
[2023-04-15 06:12:31,356] {taskinstance.py:1070} INFO - 
--------------------------------------------------------------------------------
[2023-04-15 06:12:31,685] {logging_mixin.py:104} WARNING - --- Logging error ---
--- Logging error ---
--- Logging error ---
--- Logging error ---
--- Logging error ---
--- Logging error ---
--- Logging error ---
--- Logging error ---
--- Logging error ---
--- Logging error ---
--- Logging error ---
--- Logging error ---
--- Logging error ---
--- Logging error ---
--- Logging error ---
--- Logging error ---
--- Logging error ---
--- Logging error ---
--- Logging error ---
--- Logging error ---
--- Logging error ---
--- Logging error ---
--- Logging error ---
--- Logging error ---
--- Logging error ---
--- Logging error ---
--- Logging error ---
--- Logging error ---
--- Logging error ---
--- Logging error ---
--- Logging error ---
--- Logging error ---
--- Logging error ---
--- Logging error ---
--- Logging error ---
--- Logging error ---
--- Logging error ---
--- Logging error ---
--- Logging error ---
--- Logging error ---
--- Logging error ---
--- Logging error ---
--- Logging error ---
--- Logging error ---
--- Logging error ---
--- Logging error ---
--- Logging error ---
--- Logging error ---
--- Logging error ---
--- Logging error ---
--- Logging error ---
--- Logging error ---
--- Logging error ---
--- Logging error ---
--- Logging error ---
--- Logging error ---
--- Logging error ---
--- Logging error ---
--- Logging error ---
--- Logging error ---
--- Logging error ---
--- Logging error ---
--- Logging error ---
--- Logging error ---
--- Logging error ---
--- Logging error ---
--- Logging error ---
--- Logging error ---
--- Logging error ---
--- Logging error ---
--- Logging error ---
--- Logging error ---
[2023-04-15 06:12:32,306] {logging_mixin.py:104} WARNING - Traceback (most recent call last):
[2023-04-15 06:12:32,641] {logging_mixin.py:104} WARNING -   File "/usr/local/lib/python3.6/logging/__init__.py", line 998, in emit
    self.flush()
[2023-04-15 06:12:32,704] {logging_mixin.py:104} WARNING -   File "/usr/local/lib/python3.6/logging/__init__.py", line 978, in flush
    self.stream.flush()
[2023-04-15 06:12:32,753] {logging_mixin.py:104} WARNING - RuntimeError: reentrant call inside <_io.BufferedWriter name='/opt/airflow/logs/spotify_final_dag/create_table/2023-04-15T01:00:00+00:00/1.log'>
[2023-04-15 06:12:32,769] {logging_mixin.py:104} WARNING - 
During handling of the above exception, another exception occurred:
[2023-04-15 06:12:32,784] {logging_mixin.py:104} WARNING - Traceback (most recent call last):
[2023-04-15 06:12:32,820] {logging_mixin.py:104} WARNING -   File "/usr/local/lib/python3.6/logging/__init__.py", line 998, in emit
    self.flush()
[2023-04-15 06:12:32,832] {logging_mixin.py:104} WARNING -   File "/usr/local/lib/python3.6/logging/__init__.py", line 978, in flush
    self.stream.flush()
[2023-04-15 06:12:32,848] {logging_mixin.py:104} WARNING - RuntimeError: reentrant call inside <_io.BufferedWriter name='/opt/airflow/logs/spotify_final_dag/create_table/2023-04-15T01:00:00+00:00/1.log'>
[2023-04-15 06:12:32,863] {logging_mixin.py:104} WARNING - 
During handling of the above exception, another exception occurred:
[2023-04-15 06:12:32,880] {logging_mixin.py:104} WARNING - Traceback (most recent call last):
[2023-04-15 06:12:32,895] {logging_mixin.py:104} WARNING -   File "/usr/local/lib/python3.6/logging/__init__.py", line 998, in emit
    self.flush()
[2023-04-15 06:12:32,911] {logging_mixin.py:104} WARNING -   File "/usr/local/lib/python3.6/logging/__init__.py", line 978, in flush
    self.stream.flush()
[2023-04-15 06:12:32,927] {logging_mixin.py:104} WARNING - RuntimeError: reentrant call inside <_io.BufferedWriter name='/opt/airflow/logs/spotify_final_dag/create_table/2023-04-15T01:00:00+00:00/1.log'>
[2023-04-15 06:12:32,943] {logging_mixin.py:104} WARNING - 
During handling of the above exception, another exception occurred:
[2023-04-15 06:12:33,007] {logging_mixin.py:104} WARNING - Traceback (most recent call last):
[2023-04-15 06:12:33,055] {logging_mixin.py:104} WARNING -   File "/usr/local/lib/python3.6/logging/__init__.py", line 998, in emit
    self.flush()
[2023-04-15 06:12:33,119] {logging_mixin.py:104} WARNING -   File "/usr/local/lib/python3.6/logging/__init__.py", line 978, in flush
    self.stream.flush()
[2023-04-15 06:12:33,167] {logging_mixin.py:104} WARNING - RuntimeError: reentrant call inside <_io.BufferedWriter name='/opt/airflow/logs/spotify_final_dag/create_table/2023-04-15T01:00:00+00:00/1.log'>
[2023-04-15 06:12:33,183] {logging_mixin.py:104} WARNING - 
During handling of the above exception, another exception occurred:
[2023-04-15 06:12:33,201] {logging_mixin.py:104} WARNING - Traceback (most recent call last):
[2023-04-15 06:12:33,214] {logging_mixin.py:104} WARNING -   File "/usr/local/lib/python3.6/logging/__init__.py", line 998, in emit
    self.flush()
[2023-04-15 06:12:33,230] {logging_mixin.py:104} WARNING -   File "/usr/local/lib/python3.6/logging/__init__.py", line 978, in flush
    self.stream.flush()
[2023-04-15 06:12:33,247] {logging_mixin.py:104} WARNING - RuntimeError: reentrant call inside <_io.BufferedWriter name='/opt/airflow/logs/spotify_final_dag/create_table/2023-04-15T01:00:00+00:00/1.log'>
[2023-04-15 06:12:33,262] {logging_mixin.py:104} WARNING - 
During handling of the above exception, another exception occurred:
[2023-04-15 06:12:33,278] {logging_mixin.py:104} WARNING - Traceback (most recent call last):
[2023-04-15 06:12:33,294] {logging_mixin.py:104} WARNING -   File "/usr/local/lib/python3.6/logging/__init__.py", line 998, in emit
    self.flush()
[2023-04-15 06:12:33,311] {logging_mixin.py:104} WARNING -   File "/usr/local/lib/python3.6/logging/__init__.py", line 978, in flush
    self.stream.flush()
[2023-04-15 06:12:33,325] {logging_mixin.py:104} WARNING - RuntimeError: reentrant call inside <_io.BufferedWriter name='/opt/airflow/logs/spotify_final_dag/create_table/2023-04-15T01:00:00+00:00/1.log'>
[2023-04-15 06:12:33,358] {logging_mixin.py:104} WARNING - 
During handling of the above exception, another exception occurred:
[2023-04-15 06:12:33,374] {logging_mixin.py:104} WARNING - Traceback (most recent call last):
[2023-04-15 06:12:33,389] {logging_mixin.py:104} WARNING -   File "/usr/local/lib/python3.6/logging/__init__.py", line 998, in emit
    self.flush()
[2023-04-15 06:12:33,406] {logging_mixin.py:104} WARNING -   File "/usr/local/lib/python3.6/logging/__init__.py", line 978, in flush
    self.stream.flush()
[2023-04-15 06:12:33,421] {logging_mixin.py:104} WARNING - RuntimeError: reentrant call inside <_io.BufferedWriter name='/opt/airflow/logs/spotify_final_dag/create_table/2023-04-15T01:00:00+00:00/1.log'>
[2023-04-15 06:12:33,456] {logging_mixin.py:104} WARNING - 
During handling of the above exception, another exception occurred:
[2023-04-15 06:12:33,516] {logging_mixin.py:104} WARNING - Traceback (most recent call last):
[2023-04-15 06:12:33,548] {logging_mixin.py:104} WARNING -   File "/usr/local/lib/python3.6/logging/__init__.py", line 998, in emit
    self.flush()
[2023-04-15 06:12:33,611] {logging_mixin.py:104} WARNING -   File "/usr/local/lib/python3.6/logging/__init__.py", line 978, in flush
    self.stream.flush()
[2023-04-15 06:12:33,659] {logging_mixin.py:104} WARNING - RuntimeError: reentrant call inside <_io.BufferedWriter name='/opt/airflow/logs/spotify_final_dag/create_table/2023-04-15T01:00:00+00:00/1.log'>
[2023-04-15 06:12:33,676] {logging_mixin.py:104} WARNING - 
During handling of the above exception, another exception occurred:
[2023-04-15 06:12:33,691] {logging_mixin.py:104} WARNING - Traceback (most recent call last):
[2023-04-15 06:12:33,722] {logging_mixin.py:104} WARNING -   File "/usr/local/lib/python3.6/logging/__init__.py", line 998, in emit
    self.flush()
[2023-04-15 06:12:33,740] {logging_mixin.py:104} WARNING -   File "/usr/local/lib/python3.6/logging/__init__.py", line 978, in flush
    self.stream.flush()
[2023-04-15 06:12:33,754] {logging_mixin.py:104} WARNING - RuntimeError: reentrant call inside <_io.BufferedWriter name='/opt/airflow/logs/spotify_final_dag/create_table/2023-04-15T01:00:00+00:00/1.log'>
[2023-04-15 06:12:33,770] {logging_mixin.py:104} WARNING - 
During handling of the above exception, another exception occurred:
[2023-04-15 06:12:33,817] {logging_mixin.py:104} WARNING - Traceback (most recent call last):
[2023-04-15 06:12:33,833] {logging_mixin.py:104} WARNING -   File "/usr/local/lib/python3.6/logging/__init__.py", line 998, in emit
    self.flush()
[2023-04-15 06:12:33,849] {logging_mixin.py:104} WARNING -   File "/usr/local/lib/python3.6/logging/__init__.py", line 978, in flush
    self.stream.flush()
[2023-04-15 06:12:33,882] {logging_mixin.py:104} WARNING - RuntimeError: reentrant call inside <_io.BufferedWriter name='/opt/airflow/logs/spotify_final_dag/create_table/2023-04-15T01:00:00+00:00/1.log'>
[2023-04-15 06:12:33,898] {logging_mixin.py:104} WARNING - 
During handling of the above exception, another exception occurred:
[2023-04-15 06:12:33,913] {logging_mixin.py:104} WARNING - Traceback (most recent call last):
[2023-04-15 06:12:33,929] {logging_mixin.py:104} WARNING -   File "/usr/local/lib/python3.6/logging/__init__.py", line 998, in emit
    self.flush()
[2023-04-15 06:12:33,945] {logging_mixin.py:104} WARNING -   File "/usr/local/lib/python3.6/logging/__init__.py", line 978, in flush
    self.stream.flush()
[2023-04-15 06:12:33,977] {logging_mixin.py:104} WARNING - RuntimeError: reentrant call inside <_io.BufferedWriter name='/opt/airflow/logs/spotify_final_dag/create_table/2023-04-15T01:00:00+00:00/1.log'>
[2023-04-15 06:12:34,043] {logging_mixin.py:104} WARNING - 
During handling of the above exception, another exception occurred:
[2023-04-15 06:12:34,088] {logging_mixin.py:104} WARNING - Traceback (most recent call last):
[2023-04-15 06:12:34,104] {logging_mixin.py:104} WARNING -   File "/usr/local/lib/python3.6/logging/__init__.py", line 998, in emit
    self.flush()
[2023-04-15 06:12:34,120] {logging_mixin.py:104} WARNING -   File "/usr/local/lib/python3.6/logging/__init__.py", line 978, in flush
    self.stream.flush()
[2023-04-15 06:12:34,136] {logging_mixin.py:104} WARNING - RuntimeError: reentrant call inside <_io.BufferedWriter name='/opt/airflow/logs/spotify_final_dag/create_table/2023-04-15T01:00:00+00:00/1.log'>
[2023-04-15 06:12:34,152] {logging_mixin.py:104} WARNING - 
During handling of the above exception, another exception occurred:
[2023-04-15 06:12:34,154] {logging_mixin.py:104} WARNING - Traceback (most recent call last):
[2023-04-15 06:12:34,167] {logging_mixin.py:104} WARNING -   File "/usr/local/lib/python3.6/logging/__init__.py", line 998, in emit
    self.flush()
[2023-04-15 06:12:34,199] {logging_mixin.py:104} WARNING -   File "/usr/local/lib/python3.6/logging/__init__.py", line 978, in flush
    self.stream.flush()
[2023-04-15 06:12:34,200] {logging_mixin.py:104} WARNING - RuntimeError: reentrant call inside <_io.BufferedWriter name='/opt/airflow/logs/spotify_final_dag/create_table/2023-04-15T01:00:00+00:00/1.log'>
[2023-04-15 06:12:34,215] {logging_mixin.py:104} WARNING - 
During handling of the above exception, another exception occurred:
[2023-04-15 06:12:34,246] {logging_mixin.py:104} WARNING - Traceback (most recent call last):
[2023-04-15 06:12:34,262] {logging_mixin.py:104} WARNING -   File "/usr/local/lib/python3.6/logging/__init__.py", line 998, in emit
    self.flush()
[2023-04-15 06:12:34,278] {logging_mixin.py:104} WARNING -   File "/usr/local/lib/python3.6/logging/__init__.py", line 978, in flush
    self.stream.flush()
[2023-04-15 06:12:34,294] {logging_mixin.py:104} WARNING - RuntimeError: reentrant call inside <_io.BufferedWriter name='/opt/airflow/logs/spotify_final_dag/create_table/2023-04-15T01:00:00+00:00/1.log'>
[2023-04-15 06:12:34,310] {logging_mixin.py:104} WARNING - 
During handling of the above exception, another exception occurred:
[2023-04-15 06:12:34,326] {logging_mixin.py:104} WARNING - Traceback (most recent call last):
[2023-04-15 06:12:34,343] {logging_mixin.py:104} WARNING -   File "/usr/local/lib/python3.6/logging/__init__.py", line 998, in emit
    self.flush()
[2023-04-15 06:12:34,358] {logging_mixin.py:104} WARNING -   File "/usr/local/lib/python3.6/logging/__init__.py", line 978, in flush
    self.stream.flush()
[2023-04-15 06:12:34,374] {logging_mixin.py:104} WARNING - RuntimeError: reentrant call inside <_io.BufferedWriter name='/opt/airflow/logs/spotify_final_dag/create_table/2023-04-15T01:00:00+00:00/1.log'>
[2023-04-15 06:12:34,390] {logging_mixin.py:104} WARNING - 
During handling of the above exception, another exception occurred:
[2023-04-15 06:12:34,406] {logging_mixin.py:104} WARNING - Traceback (most recent call last):
[2023-04-15 06:12:34,485] {logging_mixin.py:104} WARNING -   File "/usr/local/lib/python3.6/logging/__init__.py", line 998, in emit
    self.flush()
[2023-04-15 06:12:34,501] {logging_mixin.py:104} WARNING -   File "/usr/local/lib/python3.6/logging/__init__.py", line 978, in flush
    self.stream.flush()
[2023-04-15 06:12:34,533] {logging_mixin.py:104} WARNING - RuntimeError: reentrant call inside <_io.BufferedWriter name='/opt/airflow/logs/spotify_final_dag/create_table/2023-04-15T01:00:00+00:00/1.log'>
[2023-04-15 06:12:34,551] {logging_mixin.py:104} WARNING - 
During handling of the above exception, another exception occurred:
[2023-04-15 06:12:34,613] {logging_mixin.py:104} WARNING - Traceback (most recent call last):
[2023-04-15 06:12:34,644] {logging_mixin.py:104} WARNING -   File "/usr/local/lib/python3.6/logging/__init__.py", line 998, in emit
    self.flush()
[2023-04-15 06:12:34,707] {logging_mixin.py:104} WARNING -   File "/usr/local/lib/python3.6/logging/__init__.py", line 978, in flush
    self.stream.flush()
[2023-04-15 06:12:34,739] {logging_mixin.py:104} WARNING - RuntimeError: reentrant call inside <_io.BufferedWriter name='/opt/airflow/logs/spotify_final_dag/create_table/2023-04-15T01:00:00+00:00/1.log'>
[2023-04-15 06:12:34,755] {logging_mixin.py:104} WARNING - 
During handling of the above exception, another exception occurred:
[2023-04-15 06:12:34,771] {logging_mixin.py:104} WARNING - Traceback (most recent call last):
[2023-04-15 06:12:34,788] {logging_mixin.py:104} WARNING -   File "/usr/local/lib/python3.6/logging/__init__.py", line 998, in emit
    self.flush()
[2023-04-15 06:12:34,804] {logging_mixin.py:104} WARNING -   File "/usr/local/lib/python3.6/logging/__init__.py", line 978, in flush
    self.stream.flush()
[2023-04-15 06:12:34,819] {logging_mixin.py:104} WARNING - RuntimeError: reentrant call inside <_io.BufferedWriter name='/opt/airflow/logs/spotify_final_dag/create_table/2023-04-15T01:00:00+00:00/1.log'>
[2023-04-15 06:12:34,852] {logging_mixin.py:104} WARNING - 
During handling of the above exception, another exception occurred:
[2023-04-15 06:12:34,866] {logging_mixin.py:104} WARNING - Traceback (most recent call last):
[2023-04-15 06:12:34,915] {logging_mixin.py:104} WARNING -   File "/usr/local/lib/python3.6/logging/__init__.py", line 998, in emit
    self.flush()
[2023-04-15 06:12:34,948] {logging_mixin.py:104} WARNING -   File "/usr/local/lib/python3.6/logging/__init__.py", line 978, in flush
    self.stream.flush()
[2023-04-15 06:12:34,980] {logging_mixin.py:104} WARNING - RuntimeError: reentrant call inside <_io.BufferedWriter name='/opt/airflow/logs/spotify_final_dag/create_table/2023-04-15T01:00:00+00:00/1.log'>
[2023-04-15 06:12:34,996] {logging_mixin.py:104} WARNING - 
During handling of the above exception, another exception occurred:
[2023-04-15 06:12:35,043] {logging_mixin.py:104} WARNING - Traceback (most recent call last):
[2023-04-15 06:12:35,057] {logging_mixin.py:104} WARNING -   File "/usr/local/lib/python3.6/logging/__init__.py", line 998, in emit
    self.flush()
[2023-04-15 06:12:35,105] {logging_mixin.py:104} WARNING -   File "/usr/local/lib/python3.6/logging/__init__.py", line 978, in flush
    self.stream.flush()
[2023-04-15 06:12:35,137] {logging_mixin.py:104} WARNING - RuntimeError: reentrant call inside <_io.BufferedWriter name='/opt/airflow/logs/spotify_final_dag/create_table/2023-04-15T01:00:00+00:00/1.log'>
[2023-04-15 06:12:35,168] {logging_mixin.py:104} WARNING - 
During handling of the above exception, another exception occurred:
[2023-04-15 06:12:35,186] {logging_mixin.py:104} WARNING - Traceback (most recent call last):
[2023-04-15 06:12:35,202] {logging_mixin.py:104} WARNING -   File "/usr/local/lib/python3.6/logging/__init__.py", line 998, in emit
    self.flush()
[2023-04-15 06:12:35,216] {logging_mixin.py:104} WARNING -   File "/usr/local/lib/python3.6/logging/__init__.py", line 978, in flush
    self.stream.flush()
[2023-04-15 06:12:35,232] {logging_mixin.py:104} WARNING - RuntimeError: reentrant call inside <_io.BufferedWriter name='/opt/airflow/logs/spotify_final_dag/create_table/2023-04-15T01:00:00+00:00/1.log'>
[2023-04-15 06:12:35,248] {logging_mixin.py:104} WARNING - 
During handling of the above exception, another exception occurred:
[2023-04-15 06:12:35,263] {logging_mixin.py:104} WARNING - Traceback (most recent call last):
[2023-04-15 06:12:35,279] {logging_mixin.py:104} WARNING -   File "/usr/local/lib/python3.6/logging/__init__.py", line 998, in emit
    self.flush()
[2023-04-15 06:12:35,295] {logging_mixin.py:104} WARNING -   File "/usr/local/lib/python3.6/logging/__init__.py", line 978, in flush
    self.stream.flush()
[2023-04-15 06:12:35,311] {logging_mixin.py:104} WARNING - RuntimeError: reentrant call inside <_io.BufferedWriter name='/opt/airflow/logs/spotify_final_dag/create_table/2023-04-15T01:00:00+00:00/1.log'>
[2023-04-15 06:12:35,327] {logging_mixin.py:104} WARNING - 
During handling of the above exception, another exception occurred:
[2023-04-15 06:12:35,374] {logging_mixin.py:104} WARNING - Traceback (most recent call last):
[2023-04-15 06:12:35,406] {logging_mixin.py:104} WARNING -   File "/usr/local/lib/python3.6/logging/__init__.py", line 998, in emit
    self.flush()
[2023-04-15 06:12:35,469] {logging_mixin.py:104} WARNING -   File "/usr/local/lib/python3.6/logging/__init__.py", line 978, in flush
    self.stream.flush()
[2023-04-15 06:12:35,517] {logging_mixin.py:104} WARNING - RuntimeError: reentrant call inside <_io.BufferedWriter name='/opt/airflow/logs/spotify_final_dag/create_table/2023-04-15T01:00:00+00:00/1.log'>
[2023-04-15 06:12:35,564] {logging_mixin.py:104} WARNING - 
During handling of the above exception, another exception occurred:
[2023-04-15 06:12:35,581] {logging_mixin.py:104} WARNING - Traceback (most recent call last):
[2023-04-15 06:12:35,643] {logging_mixin.py:104} WARNING -   File "/usr/local/lib/python3.6/logging/__init__.py", line 998, in emit
    self.flush()
[2023-04-15 06:12:35,740] {logging_mixin.py:104} WARNING -   File "/usr/local/lib/python3.6/logging/__init__.py", line 978, in flush
    self.stream.flush()
[2023-04-15 06:12:35,772] {logging_mixin.py:104} WARNING - RuntimeError: reentrant call inside <_io.BufferedWriter name='/opt/airflow/logs/spotify_final_dag/create_table/2023-04-15T01:00:00+00:00/1.log'>
[2023-04-15 06:12:35,788] {logging_mixin.py:104} WARNING - 
During handling of the above exception, another exception occurred:
[2023-04-15 06:12:35,821] {logging_mixin.py:104} WARNING - Traceback (most recent call last):
[2023-04-15 06:12:35,836] {logging_mixin.py:104} WARNING -   File "/usr/local/lib/python3.6/logging/__init__.py", line 998, in emit
    self.flush()
[2023-04-15 06:12:35,852] {logging_mixin.py:104} WARNING -   File "/usr/local/lib/python3.6/logging/__init__.py", line 978, in flush
    self.stream.flush()
[2023-04-15 06:12:35,868] {logging_mixin.py:104} WARNING - RuntimeError: reentrant call inside <_io.BufferedWriter name='/opt/airflow/logs/spotify_final_dag/create_table/2023-04-15T01:00:00+00:00/1.log'>
[2023-04-15 06:12:35,887] {logging_mixin.py:104} WARNING - 
During handling of the above exception, another exception occurred:
[2023-04-15 06:12:35,899] {logging_mixin.py:104} WARNING - Traceback (most recent call last):
[2023-04-15 06:12:35,948] {logging_mixin.py:104} WARNING -   File "/usr/local/lib/python3.6/logging/__init__.py", line 998, in emit
    self.flush()
[2023-04-15 06:12:35,996] {logging_mixin.py:104} WARNING -   File "/usr/local/lib/python3.6/logging/__init__.py", line 978, in flush
    self.stream.flush()
[2023-04-15 06:12:36,059] {logging_mixin.py:104} WARNING - RuntimeError: reentrant call inside <_io.BufferedWriter name='/opt/airflow/logs/spotify_final_dag/create_table/2023-04-15T01:00:00+00:00/1.log'>
[2023-04-15 06:12:36,091] {logging_mixin.py:104} WARNING - 
During handling of the above exception, another exception occurred:
[2023-04-15 06:12:36,107] {logging_mixin.py:104} WARNING - Traceback (most recent call last):
[2023-04-15 06:12:36,125] {logging_mixin.py:104} WARNING -   File "/usr/local/lib/python3.6/logging/__init__.py", line 998, in emit
    self.flush()
[2023-04-15 06:12:36,139] {logging_mixin.py:104} WARNING -   File "/usr/local/lib/python3.6/logging/__init__.py", line 978, in flush
    self.stream.flush()
[2023-04-15 06:12:36,155] {logging_mixin.py:104} WARNING - RuntimeError: reentrant call inside <_io.BufferedWriter name='/opt/airflow/logs/spotify_final_dag/create_table/2023-04-15T01:00:00+00:00/1.log'>
[2023-04-15 06:12:36,171] {logging_mixin.py:104} WARNING - 
During handling of the above exception, another exception occurred:
[2023-04-15 06:12:36,188] {logging_mixin.py:104} WARNING - Traceback (most recent call last):
[2023-04-15 06:12:36,220] {logging_mixin.py:104} WARNING -   File "/usr/local/lib/python3.6/logging/__init__.py", line 998, in emit
    self.flush()
[2023-04-15 06:12:36,253] {logging_mixin.py:104} WARNING -   File "/usr/local/lib/python3.6/logging/__init__.py", line 978, in flush
    self.stream.flush()
[2023-04-15 06:12:36,335] {logging_mixin.py:104} WARNING - RuntimeError: reentrant call inside <_io.BufferedWriter name='/opt/airflow/logs/spotify_final_dag/create_table/2023-04-15T01:00:00+00:00/1.log'>
[2023-04-15 06:12:36,396] {logging_mixin.py:104} WARNING - 
During handling of the above exception, another exception occurred:
[2023-04-15 06:12:36,476] {logging_mixin.py:104} WARNING - Traceback (most recent call last):
[2023-04-15 06:12:36,508] {logging_mixin.py:104} WARNING -   File "/usr/local/lib/python3.6/logging/__init__.py", line 998, in emit
    self.flush()
[2023-04-15 06:12:36,524] {logging_mixin.py:104} WARNING -   File "/usr/local/lib/python3.6/logging/__init__.py", line 978, in flush
    self.stream.flush()
[2023-04-15 06:12:36,572] {logging_mixin.py:104} WARNING - RuntimeError: reentrant call inside <_io.BufferedWriter name='/opt/airflow/logs/spotify_final_dag/create_table/2023-04-15T01:00:00+00:00/1.log'>
[2023-04-15 06:12:36,621] {logging_mixin.py:104} WARNING - 
During handling of the above exception, another exception occurred:
[2023-04-15 06:12:36,637] {logging_mixin.py:104} WARNING - Traceback (most recent call last):
[2023-04-15 06:12:36,653] {logging_mixin.py:104} WARNING -   File "/usr/local/lib/python3.6/logging/__init__.py", line 998, in emit
    self.flush()
[2023-04-15 06:12:36,671] {logging_mixin.py:104} WARNING -   File "/usr/local/lib/python3.6/logging/__init__.py", line 978, in flush
    self.stream.flush()
[2023-04-15 06:12:36,685] {logging_mixin.py:104} WARNING - RuntimeError: reentrant call inside <_io.BufferedWriter name='/opt/airflow/logs/spotify_final_dag/create_table/2023-04-15T01:00:00+00:00/1.log'>
[2023-04-15 06:12:36,701] {logging_mixin.py:104} WARNING - 
During handling of the above exception, another exception occurred:
[2023-04-15 06:12:36,749] {logging_mixin.py:104} WARNING - Traceback (most recent call last):
[2023-04-15 06:12:36,814] {logging_mixin.py:104} WARNING -   File "/usr/local/lib/python3.6/logging/__init__.py", line 998, in emit
    self.flush()
[2023-04-15 06:12:36,878] {logging_mixin.py:104} WARNING -   File "/usr/local/lib/python3.6/logging/__init__.py", line 978, in flush
    self.stream.flush()
[2023-04-15 06:12:36,894] {logging_mixin.py:104} WARNING - RuntimeError: reentrant call inside <_io.BufferedWriter name='/opt/airflow/logs/spotify_final_dag/create_table/2023-04-15T01:00:00+00:00/1.log'>
[2023-04-15 06:12:36,910] {logging_mixin.py:104} WARNING - 
During handling of the above exception, another exception occurred:
[2023-04-15 06:12:36,926] {logging_mixin.py:104} WARNING - Traceback (most recent call last):
[2023-04-15 06:12:36,943] {logging_mixin.py:104} WARNING -   File "/usr/local/lib/python3.6/logging/__init__.py", line 998, in emit
    self.flush()
[2023-04-15 06:12:36,959] {logging_mixin.py:104} WARNING -   File "/usr/local/lib/python3.6/logging/__init__.py", line 978, in flush
    self.stream.flush()
[2023-04-15 06:12:36,975] {logging_mixin.py:104} WARNING - RuntimeError: reentrant call inside <_io.BufferedWriter name='/opt/airflow/logs/spotify_final_dag/create_table/2023-04-15T01:00:00+00:00/1.log'>
[2023-04-15 06:12:36,993] {logging_mixin.py:104} WARNING - 
During handling of the above exception, another exception occurred:
[2023-04-15 06:12:37,007] {logging_mixin.py:104} WARNING - Traceback (most recent call last):
[2023-04-15 06:12:37,023] {logging_mixin.py:104} WARNING -   File "/usr/local/lib/python3.6/logging/__init__.py", line 998, in emit
    self.flush()
[2023-04-15 06:12:37,039] {logging_mixin.py:104} WARNING -   File "/usr/local/lib/python3.6/logging/__init__.py", line 978, in flush
    self.stream.flush()
[2023-04-15 06:12:37,056] {logging_mixin.py:104} WARNING - RuntimeError: reentrant call inside <_io.BufferedWriter name='/opt/airflow/logs/spotify_final_dag/create_table/2023-04-15T01:00:00+00:00/1.log'>
[2023-04-15 06:12:37,071] {logging_mixin.py:104} WARNING - 
During handling of the above exception, another exception occurred:
[2023-04-15 06:12:37,087] {logging_mixin.py:104} WARNING - Traceback (most recent call last):
[2023-04-15 06:12:37,103] {logging_mixin.py:104} WARNING -   File "/usr/local/lib/python3.6/logging/__init__.py", line 998, in emit
    self.flush()
[2023-04-15 06:12:37,119] {logging_mixin.py:104} WARNING -   File "/usr/local/lib/python3.6/logging/__init__.py", line 978, in flush
    self.stream.flush()
[2023-04-15 06:12:37,135] {logging_mixin.py:104} WARNING - RuntimeError: reentrant call inside <_io.BufferedWriter name='/opt/airflow/logs/spotify_final_dag/create_table/2023-04-15T01:00:00+00:00/1.log'>
[2023-04-15 06:12:37,183] {logging_mixin.py:104} WARNING - 
During handling of the above exception, another exception occurred:
[2023-04-15 06:12:37,280] {logging_mixin.py:104} WARNING - Traceback (most recent call last):
[2023-04-15 06:12:37,312] {logging_mixin.py:104} WARNING -   File "/usr/local/lib/python3.6/logging/__init__.py", line 998, in emit
    self.flush()
[2023-04-15 06:12:37,328] {logging_mixin.py:104} WARNING -   File "/usr/local/lib/python3.6/logging/__init__.py", line 978, in flush
    self.stream.flush()
[2023-04-15 06:12:37,344] {logging_mixin.py:104} WARNING - RuntimeError: reentrant call inside <_io.BufferedWriter name='/opt/airflow/logs/spotify_final_dag/create_table/2023-04-15T01:00:00+00:00/1.log'>
